import {
  ConflictException,
  InternalServerErrorException,
} from '@nestjs/common';
import { EntityRepository, Repository } from 'typeorm';
import { AuthCredentialsDTO } from './DTOs/auth-credentials.dto';
import { User } from './user.entity';
import * as bcrypt from 'bcrypt';

@EntityRepository(User)
export class UsersRepository extends Repository<User> {
  public async createUser(
    authCredentialsDTO: AuthCredentialsDTO,
  ): Promise<void> {
    const { username, password } = authCredentialsDTO;

    const salt = await bcrypt.genSalt();
    const hashedPassword = await bcrypt.hash(password, salt);

    const user = this.create({
      username,
      password: hashedPassword,
    });

    try {
      await this.save(user);
    } catch (error) {
      if (error.code === '23505') {
        throw new ConflictException('The username is already taken');
      } else {
        throw new InternalServerErrorException();
      }
    }
  }
}
